2025-03-26 18:10:57,112 ERROR: Exception on /admin/dashboard [GET] [in C:\Users\16673\AppData\Local\Programs\Python\Python311\Lib\site-packages\flask\app.py:1454]
Traceback (most recent call last):
  File "C:\Users\16673\AppData\Local\Programs\Python\Python311\Lib\site-packages\sqlalchemy\engine\base.py", line 1771, in _execute_context
    self.dialect.do_execute(
  File "C:\Users\16673\AppData\Local\Programs\Python\Python311\Lib\site-packages\sqlalchemy\engine\default.py", line 717, in do_execute
    cursor.execute(statement, parameters)
sqlite3.OperationalError: no such column: user.is_super_admin

The above exception was the direct cause of the following exception:

Traceback (most recent call last):
  File "C:\Users\16673\AppData\Local\Programs\Python\Python311\Lib\site-packages\flask\app.py", line 2070, in wsgi_app
    response = self.full_dispatch_request()
               ^^^^^^^^^^^^^^^^^^^^^^^^^^^^
  File "C:\Users\16673\AppData\Local\Programs\Python\Python311\Lib\site-packages\flask\app.py", line 1515, in full_dispatch_request
    rv = self.handle_user_exception(e)
         ^^^^^^^^^^^^^^^^^^^^^^^^^^^^^
  File "C:\Users\16673\AppData\Local\Programs\Python\Python311\Lib\site-packages\flask\app.py", line 1513, in full_dispatch_request
    rv = self.dispatch_request()
         ^^^^^^^^^^^^^^^^^^^^^^^
  File "C:\Users\16673\AppData\Local\Programs\Python\Python311\Lib\site-packages\flask\app.py", line 1499, in dispatch_request
    return self.ensure_sync(self.view_functions[rule.endpoint])(**req.view_args)
           ^^^^^^^^^^^^^^^^^^^^^^^^^^^^^^^^^^^^^^^^^^^^^^^^^^^^^^^^^^^^^^^^^^^^^
  File "C:\Users\16673\AppData\Local\Programs\Python\Python311\Lib\site-packages\flask_login\utils.py", line 270, in decorated_view
    elif not current_user.is_authenticated:
             ^^^^^^^^^^^^^^^^^^^^^^^^^^^^^
  File "C:\Users\16673\AppData\Local\Programs\Python\Python311\Lib\site-packages\werkzeug\local.py", line 422, in __get__
    obj = instance._get_current_object()
          ^^^^^^^^^^^^^^^^^^^^^^^^^^^^^^
  File "C:\Users\16673\AppData\Local\Programs\Python\Python311\Lib\site-packages\werkzeug\local.py", line 544, in _get_current_object
    return self.__local()  # type: ignore
           ^^^^^^^^^^^^^^
  File "C:\Users\16673\AppData\Local\Programs\Python\Python311\Lib\site-packages\flask_login\utils.py", line 26, in <lambda>
    current_user = LocalProxy(lambda: _get_user())
                                      ^^^^^^^^^^^
  File "C:\Users\16673\AppData\Local\Programs\Python\Python311\Lib\site-packages\flask_login\utils.py", line 346, in _get_user
    current_app.login_manager._load_user()
  File "C:\Users\16673\AppData\Local\Programs\Python\Python311\Lib\site-packages\flask_login\login_manager.py", line 318, in _load_user
    user = self._user_callback(user_id)
           ^^^^^^^^^^^^^^^^^^^^^^^^^^^^
  File "c:\Users\16673\Desktop\论坛1\app.py", line 87, in load_user
    return User.query.get(int(user_id))
           ^^^^^^^^^^^^^^^^^^^^^^^^^^^^
  File "<string>", line 2, in get
  File "C:\Users\16673\AppData\Local\Programs\Python\Python311\Lib\site-packages\sqlalchemy\util\deprecations.py", line 390, in warned
    return fn(*args, **kwargs)
           ^^^^^^^^^^^^^^^^^^^
  File "C:\Users\16673\AppData\Local\Programs\Python\Python311\Lib\site-packages\sqlalchemy\orm\query.py", line 943, in get
    return self._get_impl(ident, loading.load_on_pk_identity)
           ^^^^^^^^^^^^^^^^^^^^^^^^^^^^^^^^^^^^^^^^^^^^^^^^^^
  File "C:\Users\16673\AppData\Local\Programs\Python\Python311\Lib\site-packages\sqlalchemy\orm\query.py", line 947, in _get_impl
    return self.session._get_impl(
           ^^^^^^^^^^^^^^^^^^^^^^^
  File "C:\Users\16673\AppData\Local\Programs\Python\Python311\Lib\site-packages\sqlalchemy\orm\session.py", line 2839, in _get_impl
    return db_load_fn(
           ^^^^^^^^^^^
  File "C:\Users\16673\AppData\Local\Programs\Python\Python311\Lib\site-packages\sqlalchemy\orm\loading.py", line 524, in load_on_pk_identity
    session.execute(
  File "C:\Users\16673\AppData\Local\Programs\Python\Python311\Lib\site-packages\sqlalchemy\orm\session.py", line 1689, in execute
    result = conn._execute_20(statement, params or {}, execution_options)
             ^^^^^^^^^^^^^^^^^^^^^^^^^^^^^^^^^^^^^^^^^^^^^^^^^^^^^^^^^^^^
  File "C:\Users\16673\AppData\Local\Programs\Python\Python311\Lib\site-packages\sqlalchemy\engine\base.py", line 1583, in _execute_20
    return meth(self, args_10style, kwargs_10style, execution_options)
           ^^^^^^^^^^^^^^^^^^^^^^^^^^^^^^^^^^^^^^^^^^^^^^^^^^^^^^^^^^^
  File "C:\Users\16673\AppData\Local\Programs\Python\Python311\Lib\site-packages\sqlalchemy\sql\elements.py", line 323, in _execute_on_connection
    return connection._execute_clauseelement(
           ^^^^^^^^^^^^^^^^^^^^^^^^^^^^^^^^^^
  File "C:\Users\16673\AppData\Local\Programs\Python\Python311\Lib\site-packages\sqlalchemy\engine\base.py", line 1452, in _execute_clauseelement
    ret = self._execute_context(
          ^^^^^^^^^^^^^^^^^^^^^^
  File "C:\Users\16673\AppData\Local\Programs\Python\Python311\Lib\site-packages\sqlalchemy\engine\base.py", line 1814, in _execute_context
    self._handle_dbapi_exception(
  File "C:\Users\16673\AppData\Local\Programs\Python\Python311\Lib\site-packages\sqlalchemy\engine\base.py", line 1995, in _handle_dbapi_exception
    util.raise_(
  File "C:\Users\16673\AppData\Local\Programs\Python\Python311\Lib\site-packages\sqlalchemy\util\compat.py", line 207, in raise_
    raise exception
  File "C:\Users\16673\AppData\Local\Programs\Python\Python311\Lib\site-packages\sqlalchemy\engine\base.py", line 1771, in _execute_context
    self.dialect.do_execute(
  File "C:\Users\16673\AppData\Local\Programs\Python\Python311\Lib\site-packages\sqlalchemy\engine\default.py", line 717, in do_execute
    cursor.execute(statement, parameters)
sqlalchemy.exc.OperationalError: (sqlite3.OperationalError) no such column: user.is_super_admin
[SQL: SELECT user.id AS user_id, user.username AS user_username, user.password_hash AS user_password_hash, user.avatar AS user_avatar, user.bio AS user_bio, user.location AS user_location, user.is_admin AS user_is_admin, user.is_super_admin AS user_is_super_admin, user.date_joined AS user_date_joined 
FROM user 
WHERE user.id = ?]
[parameters: (1,)]
(Background on this error at: https://sqlalche.me/e/14/e3q8)
2025-03-26 18:10:57,151 ERROR: Server Error: 500 Internal Server Error: The server encountered an internal error and was unable to complete your request. Either the server is overloaded or there is an error in the application. [in c:\Users\16673\Desktop\论坛1\app.py:40]
2025-03-26 18:11:06,202 INFO: 论坛启动 [in c:\Users\16673\Desktop\论坛1\app.py:29]
2025-03-26 18:11:10,843 INFO: 论坛启动 [in c:\Users\16673\Desktop\论坛1\app.py:29]
2025-03-26 18:29:28,822 INFO: 论坛启动 [in c:\Users\16673\Desktop\论坛1\app.py:29]
2025-03-26 18:31:03,640 INFO: 论坛启动 [in c:\Users\16673\Desktop\论坛1\app.py:29]
